{
  "cells": [
    {
      "cell_type": "markdown",
      "metadata": {
        "id": "view-in-github",
        "colab_type": "text"
      },
      "source": [
        "<a href=\"https://colab.research.google.com/github/snehasingh0203/LONGFORMER_TWEET-SUMMARIZATION/blob/main/Longfromer_tweet_summarization.ipynb\" target=\"_parent\"><img src=\"https://colab.research.google.com/assets/colab-badge.svg\" alt=\"Open In Colab\"/></a>"
      ]
    },
    {
      "cell_type": "markdown",
      "metadata": {
        "id": "3cMR7M6z7PpE"
      },
      "source": [
        "# ***SUMMARIZATION USING LONGFORMER MODEL***\n"
      ]
    },
    {
      "cell_type": "code",
      "execution_count": null,
      "metadata": {
        "colab": {
          "base_uri": "https://localhost:8080/"
        },
        "id": "3tXwXQ-A7AZh",
        "outputId": "c154f762-cb7c-4965-e2be-b69eccb9d01a"
      },
      "outputs": [
        {
          "name": "stdout",
          "output_type": "stream",
          "text": [
            "Requirement already satisfied: transformers in /usr/local/lib/python3.10/dist-packages (4.31.0)\n",
            "Requirement already satisfied: filelock in /usr/local/lib/python3.10/dist-packages (from transformers) (3.12.2)\n",
            "Requirement already satisfied: huggingface-hub<1.0,>=0.14.1 in /usr/local/lib/python3.10/dist-packages (from transformers) (0.16.4)\n",
            "Requirement already satisfied: numpy>=1.17 in /usr/local/lib/python3.10/dist-packages (from transformers) (1.23.5)\n",
            "Requirement already satisfied: packaging>=20.0 in /usr/local/lib/python3.10/dist-packages (from transformers) (23.1)\n",
            "Requirement already satisfied: pyyaml>=5.1 in /usr/local/lib/python3.10/dist-packages (from transformers) (6.0.1)\n",
            "Requirement already satisfied: regex!=2019.12.17 in /usr/local/lib/python3.10/dist-packages (from transformers) (2023.6.3)\n",
            "Requirement already satisfied: requests in /usr/local/lib/python3.10/dist-packages (from transformers) (2.31.0)\n",
            "Requirement already satisfied: tokenizers!=0.11.3,<0.14,>=0.11.1 in /usr/local/lib/python3.10/dist-packages (from transformers) (0.13.3)\n",
            "Requirement already satisfied: safetensors>=0.3.1 in /usr/local/lib/python3.10/dist-packages (from transformers) (0.3.2)\n",
            "Requirement already satisfied: tqdm>=4.27 in /usr/local/lib/python3.10/dist-packages (from transformers) (4.66.0)\n",
            "Requirement already satisfied: fsspec in /usr/local/lib/python3.10/dist-packages (from huggingface-hub<1.0,>=0.14.1->transformers) (2023.6.0)\n",
            "Requirement already satisfied: typing-extensions>=3.7.4.3 in /usr/local/lib/python3.10/dist-packages (from huggingface-hub<1.0,>=0.14.1->transformers) (4.7.1)\n",
            "Requirement already satisfied: charset-normalizer<4,>=2 in /usr/local/lib/python3.10/dist-packages (from requests->transformers) (3.2.0)\n",
            "Requirement already satisfied: idna<4,>=2.5 in /usr/local/lib/python3.10/dist-packages (from requests->transformers) (3.4)\n",
            "Requirement already satisfied: urllib3<3,>=1.21.1 in /usr/local/lib/python3.10/dist-packages (from requests->transformers) (2.0.4)\n",
            "Requirement already satisfied: certifi>=2017.4.17 in /usr/local/lib/python3.10/dist-packages (from requests->transformers) (2023.7.22)\n",
            "Requirement already satisfied: tensorflow in /usr/local/lib/python3.10/dist-packages (2.12.0)\n",
            "Requirement already satisfied: absl-py>=1.0.0 in /usr/local/lib/python3.10/dist-packages (from tensorflow) (1.4.0)\n",
            "Requirement already satisfied: astunparse>=1.6.0 in /usr/local/lib/python3.10/dist-packages (from tensorflow) (1.6.3)\n",
            "Requirement already satisfied: flatbuffers>=2.0 in /usr/local/lib/python3.10/dist-packages (from tensorflow) (23.5.26)\n",
            "Requirement already satisfied: gast<=0.4.0,>=0.2.1 in /usr/local/lib/python3.10/dist-packages (from tensorflow) (0.4.0)\n",
            "Requirement already satisfied: google-pasta>=0.1.1 in /usr/local/lib/python3.10/dist-packages (from tensorflow) (0.2.0)\n",
            "Requirement already satisfied: grpcio<2.0,>=1.24.3 in /usr/local/lib/python3.10/dist-packages (from tensorflow) (1.56.2)\n",
            "Requirement already satisfied: h5py>=2.9.0 in /usr/local/lib/python3.10/dist-packages (from tensorflow) (3.9.0)\n",
            "Requirement already satisfied: jax>=0.3.15 in /usr/local/lib/python3.10/dist-packages (from tensorflow) (0.4.14)\n",
            "Requirement already satisfied: keras<2.13,>=2.12.0 in /usr/local/lib/python3.10/dist-packages (from tensorflow) (2.12.0)\n",
            "Requirement already satisfied: libclang>=13.0.0 in /usr/local/lib/python3.10/dist-packages (from tensorflow) (16.0.6)\n",
            "Requirement already satisfied: numpy<1.24,>=1.22 in /usr/local/lib/python3.10/dist-packages (from tensorflow) (1.23.5)\n",
            "Requirement already satisfied: opt-einsum>=2.3.2 in /usr/local/lib/python3.10/dist-packages (from tensorflow) (3.3.0)\n",
            "Requirement already satisfied: packaging in /usr/local/lib/python3.10/dist-packages (from tensorflow) (23.1)\n",
            "Requirement already satisfied: protobuf!=4.21.0,!=4.21.1,!=4.21.2,!=4.21.3,!=4.21.4,!=4.21.5,<5.0.0dev,>=3.20.3 in /usr/local/lib/python3.10/dist-packages (from tensorflow) (3.20.3)\n",
            "Requirement already satisfied: setuptools in /usr/local/lib/python3.10/dist-packages (from tensorflow) (67.7.2)\n",
            "Requirement already satisfied: six>=1.12.0 in /usr/local/lib/python3.10/dist-packages (from tensorflow) (1.16.0)\n",
            "Requirement already satisfied: tensorboard<2.13,>=2.12 in /usr/local/lib/python3.10/dist-packages (from tensorflow) (2.12.3)\n",
            "Requirement already satisfied: tensorflow-estimator<2.13,>=2.12.0 in /usr/local/lib/python3.10/dist-packages (from tensorflow) (2.12.0)\n",
            "Requirement already satisfied: termcolor>=1.1.0 in /usr/local/lib/python3.10/dist-packages (from tensorflow) (2.3.0)\n",
            "Requirement already satisfied: typing-extensions>=3.6.6 in /usr/local/lib/python3.10/dist-packages (from tensorflow) (4.7.1)\n",
            "Requirement already satisfied: wrapt<1.15,>=1.11.0 in /usr/local/lib/python3.10/dist-packages (from tensorflow) (1.14.1)\n",
            "Requirement already satisfied: tensorflow-io-gcs-filesystem>=0.23.1 in /usr/local/lib/python3.10/dist-packages (from tensorflow) (0.33.0)\n",
            "Requirement already satisfied: wheel<1.0,>=0.23.0 in /usr/local/lib/python3.10/dist-packages (from astunparse>=1.6.0->tensorflow) (0.41.1)\n",
            "Requirement already satisfied: ml-dtypes>=0.2.0 in /usr/local/lib/python3.10/dist-packages (from jax>=0.3.15->tensorflow) (0.2.0)\n",
            "Requirement already satisfied: scipy>=1.7 in /usr/local/lib/python3.10/dist-packages (from jax>=0.3.15->tensorflow) (1.10.1)\n",
            "Requirement already satisfied: google-auth<3,>=1.6.3 in /usr/local/lib/python3.10/dist-packages (from tensorboard<2.13,>=2.12->tensorflow) (2.17.3)\n",
            "Requirement already satisfied: google-auth-oauthlib<1.1,>=0.5 in /usr/local/lib/python3.10/dist-packages (from tensorboard<2.13,>=2.12->tensorflow) (1.0.0)\n",
            "Requirement already satisfied: markdown>=2.6.8 in /usr/local/lib/python3.10/dist-packages (from tensorboard<2.13,>=2.12->tensorflow) (3.4.4)\n",
            "Requirement already satisfied: requests<3,>=2.21.0 in /usr/local/lib/python3.10/dist-packages (from tensorboard<2.13,>=2.12->tensorflow) (2.31.0)\n",
            "Requirement already satisfied: tensorboard-data-server<0.8.0,>=0.7.0 in /usr/local/lib/python3.10/dist-packages (from tensorboard<2.13,>=2.12->tensorflow) (0.7.1)\n",
            "Requirement already satisfied: werkzeug>=1.0.1 in /usr/local/lib/python3.10/dist-packages (from tensorboard<2.13,>=2.12->tensorflow) (2.3.6)\n",
            "Requirement already satisfied: cachetools<6.0,>=2.0.0 in /usr/local/lib/python3.10/dist-packages (from google-auth<3,>=1.6.3->tensorboard<2.13,>=2.12->tensorflow) (5.3.1)\n",
            "Requirement already satisfied: pyasn1-modules>=0.2.1 in /usr/local/lib/python3.10/dist-packages (from google-auth<3,>=1.6.3->tensorboard<2.13,>=2.12->tensorflow) (0.3.0)\n",
            "Requirement already satisfied: rsa<5,>=3.1.4 in /usr/local/lib/python3.10/dist-packages (from google-auth<3,>=1.6.3->tensorboard<2.13,>=2.12->tensorflow) (4.9)\n",
            "Requirement already satisfied: requests-oauthlib>=0.7.0 in /usr/local/lib/python3.10/dist-packages (from google-auth-oauthlib<1.1,>=0.5->tensorboard<2.13,>=2.12->tensorflow) (1.3.1)\n",
            "Requirement already satisfied: charset-normalizer<4,>=2 in /usr/local/lib/python3.10/dist-packages (from requests<3,>=2.21.0->tensorboard<2.13,>=2.12->tensorflow) (3.2.0)\n",
            "Requirement already satisfied: idna<4,>=2.5 in /usr/local/lib/python3.10/dist-packages (from requests<3,>=2.21.0->tensorboard<2.13,>=2.12->tensorflow) (3.4)\n",
            "Requirement already satisfied: urllib3<3,>=1.21.1 in /usr/local/lib/python3.10/dist-packages (from requests<3,>=2.21.0->tensorboard<2.13,>=2.12->tensorflow) (2.0.4)\n",
            "Requirement already satisfied: certifi>=2017.4.17 in /usr/local/lib/python3.10/dist-packages (from requests<3,>=2.21.0->tensorboard<2.13,>=2.12->tensorflow) (2023.7.22)\n",
            "Requirement already satisfied: MarkupSafe>=2.1.1 in /usr/local/lib/python3.10/dist-packages (from werkzeug>=1.0.1->tensorboard<2.13,>=2.12->tensorflow) (2.1.3)\n",
            "Requirement already satisfied: pyasn1<0.6.0,>=0.4.6 in /usr/local/lib/python3.10/dist-packages (from pyasn1-modules>=0.2.1->google-auth<3,>=1.6.3->tensorboard<2.13,>=2.12->tensorflow) (0.5.0)\n",
            "Requirement already satisfied: oauthlib>=3.0.0 in /usr/local/lib/python3.10/dist-packages (from requests-oauthlib>=0.7.0->google-auth-oauthlib<1.1,>=0.5->tensorboard<2.13,>=2.12->tensorflow) (3.2.2)\n",
            "Collecting git+https://github.com/huggingface/nlp.git\n",
            "  Cloning https://github.com/huggingface/nlp.git to /tmp/pip-req-build-bliq9iqa\n",
            "  Running command git clone --filter=blob:none --quiet https://github.com/huggingface/nlp.git /tmp/pip-req-build-bliq9iqa\n",
            "  Resolved https://github.com/huggingface/nlp.git to commit c02a44715c036b5261686669727394b1308a3a4b\n",
            "  Installing build dependencies ... \u001b[?25l\u001b[?25hdone\n",
            "  Getting requirements to build wheel ... \u001b[?25l\u001b[?25hdone\n",
            "  Preparing metadata (pyproject.toml) ... \u001b[?25l\u001b[?25hdone\n",
            "Requirement already satisfied: numpy>=1.17 in /usr/local/lib/python3.10/dist-packages (from datasets==2.14.4.dev0) (1.23.5)\n",
            "Requirement already satisfied: pyarrow>=8.0.0 in /usr/local/lib/python3.10/dist-packages (from datasets==2.14.4.dev0) (9.0.0)\n",
            "Requirement already satisfied: dill<0.3.8,>=0.3.0 in /usr/local/lib/python3.10/dist-packages (from datasets==2.14.4.dev0) (0.3.7)\n",
            "Requirement already satisfied: pandas in /usr/local/lib/python3.10/dist-packages (from datasets==2.14.4.dev0) (1.5.3)\n",
            "Requirement already satisfied: requests>=2.19.0 in /usr/local/lib/python3.10/dist-packages (from datasets==2.14.4.dev0) (2.31.0)\n",
            "Requirement already satisfied: tqdm>=4.62.1 in /usr/local/lib/python3.10/dist-packages (from datasets==2.14.4.dev0) (4.66.0)\n",
            "Requirement already satisfied: xxhash in /usr/local/lib/python3.10/dist-packages (from datasets==2.14.4.dev0) (3.3.0)\n",
            "Requirement already satisfied: multiprocess in /usr/local/lib/python3.10/dist-packages (from datasets==2.14.4.dev0) (0.70.15)\n",
            "Requirement already satisfied: fsspec[http]>=2022.3.0 in /usr/local/lib/python3.10/dist-packages (from datasets==2.14.4.dev0) (2023.6.0)\n",
            "Requirement already satisfied: aiohttp in /usr/local/lib/python3.10/dist-packages (from datasets==2.14.4.dev0) (3.8.5)\n",
            "Requirement already satisfied: huggingface-hub<1.0.0,>=0.14.0 in /usr/local/lib/python3.10/dist-packages (from datasets==2.14.4.dev0) (0.16.4)\n",
            "Requirement already satisfied: packaging in /usr/local/lib/python3.10/dist-packages (from datasets==2.14.4.dev0) (23.1)\n",
            "Requirement already satisfied: pyyaml>=5.1 in /usr/local/lib/python3.10/dist-packages (from datasets==2.14.4.dev0) (6.0.1)\n",
            "Requirement already satisfied: attrs>=17.3.0 in /usr/local/lib/python3.10/dist-packages (from aiohttp->datasets==2.14.4.dev0) (23.1.0)\n",
            "Requirement already satisfied: charset-normalizer<4.0,>=2.0 in /usr/local/lib/python3.10/dist-packages (from aiohttp->datasets==2.14.4.dev0) (3.2.0)\n",
            "Requirement already satisfied: multidict<7.0,>=4.5 in /usr/local/lib/python3.10/dist-packages (from aiohttp->datasets==2.14.4.dev0) (6.0.4)\n",
            "Requirement already satisfied: async-timeout<5.0,>=4.0.0a3 in /usr/local/lib/python3.10/dist-packages (from aiohttp->datasets==2.14.4.dev0) (4.0.2)\n",
            "Requirement already satisfied: yarl<2.0,>=1.0 in /usr/local/lib/python3.10/dist-packages (from aiohttp->datasets==2.14.4.dev0) (1.9.2)\n",
            "Requirement already satisfied: frozenlist>=1.1.1 in /usr/local/lib/python3.10/dist-packages (from aiohttp->datasets==2.14.4.dev0) (1.4.0)\n",
            "Requirement already satisfied: aiosignal>=1.1.2 in /usr/local/lib/python3.10/dist-packages (from aiohttp->datasets==2.14.4.dev0) (1.3.1)\n",
            "Requirement already satisfied: filelock in /usr/local/lib/python3.10/dist-packages (from huggingface-hub<1.0.0,>=0.14.0->datasets==2.14.4.dev0) (3.12.2)\n",
            "Requirement already satisfied: typing-extensions>=3.7.4.3 in /usr/local/lib/python3.10/dist-packages (from huggingface-hub<1.0.0,>=0.14.0->datasets==2.14.4.dev0) (4.7.1)\n",
            "Requirement already satisfied: idna<4,>=2.5 in /usr/local/lib/python3.10/dist-packages (from requests>=2.19.0->datasets==2.14.4.dev0) (3.4)\n",
            "Requirement already satisfied: urllib3<3,>=1.21.1 in /usr/local/lib/python3.10/dist-packages (from requests>=2.19.0->datasets==2.14.4.dev0) (2.0.4)\n",
            "Requirement already satisfied: certifi>=2017.4.17 in /usr/local/lib/python3.10/dist-packages (from requests>=2.19.0->datasets==2.14.4.dev0) (2023.7.22)\n",
            "Requirement already satisfied: python-dateutil>=2.8.1 in /usr/local/lib/python3.10/dist-packages (from pandas->datasets==2.14.4.dev0) (2.8.2)\n",
            "Requirement already satisfied: pytz>=2020.1 in /usr/local/lib/python3.10/dist-packages (from pandas->datasets==2.14.4.dev0) (2023.3)\n",
            "Requirement already satisfied: six>=1.5 in /usr/local/lib/python3.10/dist-packages (from python-dateutil>=2.8.1->pandas->datasets==2.14.4.dev0) (1.16.0)\n"
          ]
        }
      ],
      "source": [
        "!pip install transformers\n",
        "!pip install tensorflow\n",
        "from transformers import pipeline\n",
        "from transformers import AutoModelForSeq2SeqLM, AutoTokenizer\n",
        "\n",
        "!pip install git+https://github.com/huggingface/nlp.git"
      ]
    },
    {
      "cell_type": "code",
      "execution_count": null,
      "metadata": {
        "id": "NvbEihli88QD"
      },
      "outputs": [],
      "source": [
        "import torch\n",
        "from transformers import LongformerTokenizerFast"
      ]
    },
    {
      "cell_type": "code",
      "execution_count": null,
      "metadata": {
        "id": "KHfW362e9BT7"
      },
      "outputs": [],
      "source": [
        "tokenizer = LongformerTokenizerFast.from_pretrained('allenai/longformer-base-4096')"
      ]
    },
    {
      "cell_type": "code",
      "execution_count": null,
      "metadata": {
        "colab": {
          "base_uri": "https://localhost:8080/"
        },
        "id": "coao9kVw5u3y",
        "outputId": "70658ab8-ec64-4a44-ddcc-71f5d8dd81bf"
      },
      "outputs": [
        {
          "name": "stdout",
          "output_type": "stream",
          "text": [
            "Current Directory: /content/drive/MyDrive\n"
          ]
        }
      ],
      "source": [
        "import os\n",
        "\n",
        "current_directory = os.getcwd()\n",
        "print(\"Current Directory:\", current_directory)\n"
      ]
    },
    {
      "cell_type": "code",
      "execution_count": null,
      "metadata": {
        "colab": {
          "base_uri": "https://localhost:8080/"
        },
        "id": "lrEKa-uJ565G",
        "outputId": "e9ac07c4-93fd-40d2-a48a-36fe90a9cf0d"
      },
      "outputs": [
        {
          "name": "stdout",
          "output_type": "stream",
          "text": [
            "/content/drive\n",
            "/content/drive/MyDrive\n",
            " 01201_summary.gdoc\t 03492_tweet.gdoc\n",
            " 01227_summary.gdoc\t 03493_tweet.gdoc\n",
            " 01236_summary.gdoc\t 03494_tweet.gdoc\n",
            " 03451_summary.gdoc\t 03495_tweet.gdoc\n",
            "'03451_tweet (1).gdoc'\t 03496_tweet.gdoc\n",
            "'03451_tweet (2).gdoc'\t 03497_tweet.gdoc\n",
            " 03451_tweet.gdoc\t 03498_tweet.gdoc\n",
            " 03452_tweet.gdoc\t 03499_tweet.gdoc\n",
            " 03453_tweet.gdoc\t 03500_tweet.gdoc\n",
            " 03454_tweet.gdoc\t 03550_tweet.gdoc\n",
            " 03455_tweet.gdoc\t 04539_tweet.gdoc\n",
            " 03456_tweet.gdoc\t 04540_tweet.gdoc\n",
            " 03457_tweet.gdoc\t 04541_tweet.gdoc\n",
            " 03458_tweet.gdoc\t 04542_tweet.gdoc\n",
            " 03459_tweet.gdoc\t 04543_tweet.gdoc\n",
            " 03460_tweet.gdoc\t 04544_tweet.gdoc\n",
            " 03461_tweet.gdoc\t 04545_tweet.gdoc\n",
            " 03462_tweet.gdoc\t 04546_tweet.gdoc\n",
            " 03463_tweet.gdoc\t 04547_tweet.gdoc\n",
            " 03464_tweet.gdoc\t 04548_tweet.gdoc\n",
            " 03465_tweet.gdoc\t 04549_tweet.gdoc\n",
            " 03466_tweet.gdoc\t 04550_tweet.gdoc\n",
            " 03467_tweet.gdoc\t 04551_tweet.gdoc\n",
            " 03468_tweet.gdoc\t 04552_tweet.gdoc\n",
            " 03469_tweet.gdoc\t 04561_tweet.gdoc\n",
            " 03470_tweet.gdoc\t'1201 to 1205 summary'\n",
            " 03471_tweet.gdoc\t'1201 to 1300 txt files'\n",
            " 03472_tweet.gdoc\t'2901- 3000'\n",
            " 03473_tweet.gdoc\t'3401 - 3500'\n",
            " 03474_tweet.gdoc\t'3501 - 3600'\n",
            " 03475_tweet.gdoc\t'4001 - 4100'\n",
            " 03476_tweet.gdoc\t'4501 to 4600'\n",
            " 03477_tweet.gdoc\t'5601 - 5700'\n",
            " 03478_tweet.gdoc\t'5601 summs'\n",
            " 03479_tweet.gdoc\t'6201 - 6300'\n",
            " 03480_tweet.gdoc\t Aman\n",
            " 03482_tweet.gdoc\t'Colab Notebooks'\n",
            " 03483_tweet.gdoc\t'Copy of 01201_summary.gdoc'\n",
            " 03484_tweet.gdoc\t'Copy of Final_datasets'\n",
            " 03485_tweet.gdoc\t drive-download-20230724T084538Z-001.zip\n",
            " 03486_tweet.gdoc\t Final_datasets\n",
            " 03487_tweet.gdoc\t Sneha\n",
            " 03488_tweet.gdoc\t'SNEHA RESUME.docx'\n",
            " 03489_tweet.gdoc\t'Summary files 3415 to 3498'\n",
            " 03490_tweet.gdoc\t Suruchi\n",
            " 03491_tweet.gdoc\n",
            "ls: cannot access '%cd': No such file or directory\n",
            "ls: cannot access '/content/drive/MyDrive/Colab_Notebooks': No such file or directory\n"
          ]
        }
      ],
      "source": [
        "%cd /content/drive\n",
        "%cd /content/drive/MyDrive\n",
        "!ls /content/drive/MyDrive\n",
        "!ls %cd /content/drive/MyDrive/Colab_Notebooks"
      ]
    },
    {
      "cell_type": "code",
      "execution_count": null,
      "metadata": {
        "colab": {
          "base_uri": "https://localhost:8080/"
        },
        "id": "I-6pgJKR726s",
        "outputId": "031d9aea-05cf-49f2-c195-40e2d74a937d"
      },
      "outputs": [
        {
          "name": "stdout",
          "output_type": "stream",
          "text": [
            "/content/drive/MyDrive\n"
          ]
        }
      ],
      "source": [
        "!pwd"
      ]
    },
    {
      "cell_type": "code",
      "execution_count": null,
      "metadata": {
        "colab": {
          "base_uri": "https://localhost:8080/"
        },
        "id": "sqBMrlGl40if",
        "outputId": "63ad2534-aabe-47bf-c0e6-cf0a3ef89537"
      },
      "outputs": [
        {
          "name": "stdout",
          "output_type": "stream",
          "text": [
            "[Errno 2] No such file or directory: '/content/drive/MyDrive/Colab_Notebooks/Copy of Final_datasets'\n",
            "/content/drive/MyDrive\n",
            "ls: cannot access '/content/drive/MyDrive/Colab_Notebooks/Copy': No such file or directory\n",
            "ls: cannot access 'of': No such file or directory\n",
            "Final_datasets:\n",
            "Datasets.zip\n",
            "[Errno 2] No such file or directory: '/content/drive/MyDrive/Colab_Notebooks/dataset/Copy of Final_datasets'\n",
            "/content/drive/MyDrive\n"
          ]
        }
      ],
      "source": [
        "%cd /content/drive/MyDrive/Colab_Notebooks/Copy of Final_datasets\n",
        "!ls /content/drive/MyDrive/Colab_Notebooks/Copy of Final_datasets\n",
        "%cd /content/drive/MyDrive/Colab_Notebooks/dataset/Copy of Final_datasets"
      ]
    },
    {
      "cell_type": "code",
      "execution_count": null,
      "metadata": {
        "id": "MRCrMF4iApHO"
      },
      "outputs": [],
      "source": []
    },
    {
      "cell_type": "code",
      "execution_count": null,
      "metadata": {
        "id": "JjciUaBo_fPd"
      },
      "outputs": [],
      "source": [
        "from transformers import LongformerTokenizer\n",
        "\n",
        "model_name = \"allenai/longformer-base-4096\"\n",
        "tokenizer = LongformerTokenizer.from_pretrained(model_name)\n",
        "\n",
        "\n",
        "file_path = 'G:\\My Drive\\Colab Notebooks\\dataset\\Summary_files'\n",
        "dataset = [\n",
        "    {\"text\": \"This is the first document.\"}\n",
        "]\n",
        "\n",
        "features = []\n",
        "for data_sample in dataset:\n",
        "    text = data_sample[\"text\"]\n",
        "\n",
        "    inputs = tokenizer.encode_plus(\n",
        "        text,\n",
        "        add_special_tokens=True,\n",
        "        max_length=200,\n",
        "        padding='max_length',\n",
        "        truncation=True,\n",
        "        return_tensors='pt'\n",
        "    )\n",
        "\n",
        "    input_ids = inputs[\"input_ids\"]\n",
        "    attention_mask = inputs[\"attention_mask\"]\n",
        "\n",
        "\n",
        "    feature = {\n",
        "        \"input_ids\": input_ids.squeeze(),\n",
        "        \"attention_mask\": attention_mask.squeeze(),\n",
        "    }\n",
        "    features.append(feature)\n"
      ]
    },
    {
      "cell_type": "code",
      "execution_count": null,
      "metadata": {
        "id": "dpJxMM1IzdvM"
      },
      "outputs": [],
      "source": [
        "\n",
        "def summarize(text: str) -> str:\n",
        "    input_ids = tokenizer.encode(text, return_tensors='pt')\n",
        "    output_ids = model.generate(input_ids)\n",
        "    summary = tokenizer.decode(output_ids[0], skip_special_tokens=True)\n",
        "    return summary\n"
      ]
    },
    {
      "cell_type": "code",
      "execution_count": null,
      "metadata": {
        "colab": {
          "base_uri": "https://localhost:8080/"
        },
        "id": "0B-scgzqAqPn",
        "outputId": "51a519e6-94a6-4263-d7f5-ea3e6ff7f0dd"
      },
      "outputs": [
        {
          "name": "stderr",
          "output_type": "stream",
          "text": [
            "ERROR:root:Internal Python error in the inspect module.\n",
            "Below is the traceback from this internal error.\n",
            "\n",
            "ERROR:root:Internal Python error in the inspect module.\n",
            "Below is the traceback from this internal error.\n",
            "\n",
            "ERROR:root:Internal Python error in the inspect module.\n",
            "Below is the traceback from this internal error.\n",
            "\n"
          ]
        },
        {
          "name": "stdout",
          "output_type": "stream",
          "text": [
            "Traceback (most recent call last):\n",
            "  File \"/usr/local/lib/python3.10/dist-packages/IPython/core/interactiveshell.py\", line 3553, in run_code\n",
            "    exec(code_obj, self.user_global_ns, self.user_ns)\n",
            "  File \"<ipython-input-127-cdd8f5eda548>\", line 3, in <cell line: 3>\n",
            "    f = open('/content/IKDSumm_Uflood.txt\"', \"r\", encoding=\"utf8\")\n",
            "FileNotFoundError: [Errno 2] No such file or directory: '/content/IKDSumm_Uflood.txt\"'\n",
            "\n",
            "During handling of the above exception, another exception occurred:\n",
            "\n",
            "Traceback (most recent call last):\n",
            "  File \"/usr/local/lib/python3.10/dist-packages/IPython/core/interactiveshell.py\", line 2099, in showtraceback\n",
            "    stb = value._render_traceback_()\n",
            "AttributeError: 'FileNotFoundError' object has no attribute '_render_traceback_'\n",
            "\n",
            "During handling of the above exception, another exception occurred:\n",
            "\n",
            "Traceback (most recent call last):\n",
            "  File \"/usr/local/lib/python3.10/dist-packages/IPython/core/ultratb.py\", line 1101, in get_records\n",
            "    return _fixed_getinnerframes(etb, number_of_lines_of_context, tb_offset)\n",
            "  File \"/usr/local/lib/python3.10/dist-packages/IPython/core/ultratb.py\", line 248, in wrapped\n",
            "    return f(*args, **kwargs)\n",
            "  File \"/usr/local/lib/python3.10/dist-packages/IPython/core/ultratb.py\", line 281, in _fixed_getinnerframes\n",
            "    records = fix_frame_records_filenames(inspect.getinnerframes(etb, context))\n",
            "  File \"/usr/lib/python3.10/inspect.py\", line 1662, in getinnerframes\n",
            "    frameinfo = (tb.tb_frame,) + getframeinfo(tb, context)\n",
            "  File \"/usr/lib/python3.10/inspect.py\", line 1620, in getframeinfo\n",
            "    filename = getsourcefile(frame) or getfile(frame)\n",
            "  File \"/usr/lib/python3.10/inspect.py\", line 829, in getsourcefile\n",
            "    module = getmodule(object, filename)\n",
            "  File \"/usr/lib/python3.10/inspect.py\", line 861, in getmodule\n",
            "    file = getabsfile(object, _filename)\n",
            "  File \"/usr/lib/python3.10/inspect.py\", line 845, in getabsfile\n",
            "    return os.path.normcase(os.path.abspath(_filename))\n",
            "  File \"/usr/lib/python3.10/posixpath.py\", line 384, in abspath\n",
            "    cwd = os.getcwd()\n",
            "OSError: [Errno 107] Transport endpoint is not connected\n",
            "Traceback (most recent call last):\n",
            "  File \"/usr/local/lib/python3.10/dist-packages/IPython/core/interactiveshell.py\", line 3553, in run_code\n",
            "    exec(code_obj, self.user_global_ns, self.user_ns)\n",
            "  File \"<ipython-input-127-cdd8f5eda548>\", line 3, in <cell line: 3>\n",
            "    f = open('/content/IKDSumm_Uflood.txt\"', \"r\", encoding=\"utf8\")\n",
            "FileNotFoundError: [Errno 2] No such file or directory: '/content/IKDSumm_Uflood.txt\"'\n",
            "\n",
            "During handling of the above exception, another exception occurred:\n",
            "\n",
            "Traceback (most recent call last):\n",
            "  File \"/usr/local/lib/python3.10/dist-packages/IPython/core/interactiveshell.py\", line 2099, in showtraceback\n",
            "    stb = value._render_traceback_()\n",
            "AttributeError: 'FileNotFoundError' object has no attribute '_render_traceback_'\n",
            "\n",
            "During handling of the above exception, another exception occurred:\n",
            "\n",
            "Traceback (most recent call last):\n",
            "  File \"/usr/local/lib/python3.10/dist-packages/IPython/core/interactiveshell.py\", line 3473, in run_ast_nodes\n",
            "    if (await self.run_code(code, result,  async_=asy)):\n",
            "  File \"/usr/local/lib/python3.10/dist-packages/IPython/core/interactiveshell.py\", line 3575, in run_code\n",
            "    self.showtraceback(running_compiled_code=True)\n",
            "  File \"/usr/local/lib/python3.10/dist-packages/IPython/core/interactiveshell.py\", line 2101, in showtraceback\n",
            "    stb = self.InteractiveTB.structured_traceback(etype,\n",
            "  File \"/usr/local/lib/python3.10/dist-packages/IPython/core/ultratb.py\", line 1367, in structured_traceback\n",
            "    return FormattedTB.structured_traceback(\n",
            "  File \"/usr/local/lib/python3.10/dist-packages/IPython/core/ultratb.py\", line 1267, in structured_traceback\n",
            "    return VerboseTB.structured_traceback(\n",
            "  File \"/usr/local/lib/python3.10/dist-packages/IPython/core/ultratb.py\", line 1124, in structured_traceback\n",
            "    formatted_exception = self.format_exception_as_a_whole(etype, evalue, etb, number_of_lines_of_context,\n",
            "  File \"/usr/local/lib/python3.10/dist-packages/IPython/core/ultratb.py\", line 1082, in format_exception_as_a_whole\n",
            "    last_unique, recursion_repeat = find_recursion(orig_etype, evalue, records)\n",
            "  File \"/usr/local/lib/python3.10/dist-packages/IPython/core/ultratb.py\", line 382, in find_recursion\n",
            "    return len(records), 0\n",
            "TypeError: object of type 'NoneType' has no len()\n",
            "\n",
            "During handling of the above exception, another exception occurred:\n",
            "\n",
            "Traceback (most recent call last):\n",
            "  File \"/usr/local/lib/python3.10/dist-packages/IPython/core/interactiveshell.py\", line 2099, in showtraceback\n",
            "    stb = value._render_traceback_()\n",
            "AttributeError: 'TypeError' object has no attribute '_render_traceback_'\n",
            "\n",
            "During handling of the above exception, another exception occurred:\n",
            "\n",
            "Traceback (most recent call last):\n",
            "  File \"/usr/local/lib/python3.10/dist-packages/IPython/core/ultratb.py\", line 1101, in get_records\n",
            "    return _fixed_getinnerframes(etb, number_of_lines_of_context, tb_offset)\n",
            "  File \"/usr/local/lib/python3.10/dist-packages/IPython/core/ultratb.py\", line 248, in wrapped\n",
            "    return f(*args, **kwargs)\n",
            "  File \"/usr/local/lib/python3.10/dist-packages/IPython/core/ultratb.py\", line 281, in _fixed_getinnerframes\n",
            "    records = fix_frame_records_filenames(inspect.getinnerframes(etb, context))\n",
            "  File \"/usr/lib/python3.10/inspect.py\", line 1662, in getinnerframes\n",
            "    frameinfo = (tb.tb_frame,) + getframeinfo(tb, context)\n",
            "  File \"/usr/lib/python3.10/inspect.py\", line 1620, in getframeinfo\n",
            "    filename = getsourcefile(frame) or getfile(frame)\n",
            "  File \"/usr/lib/python3.10/inspect.py\", line 829, in getsourcefile\n",
            "    module = getmodule(object, filename)\n",
            "  File \"/usr/lib/python3.10/inspect.py\", line 861, in getmodule\n",
            "    file = getabsfile(object, _filename)\n",
            "  File \"/usr/lib/python3.10/inspect.py\", line 845, in getabsfile\n",
            "    return os.path.normcase(os.path.abspath(_filename))\n",
            "  File \"/usr/lib/python3.10/posixpath.py\", line 384, in abspath\n",
            "    cwd = os.getcwd()\n",
            "OSError: [Errno 107] Transport endpoint is not connected\n",
            "Traceback (most recent call last):\n",
            "  File \"/usr/local/lib/python3.10/dist-packages/IPython/core/interactiveshell.py\", line 3553, in run_code\n",
            "    exec(code_obj, self.user_global_ns, self.user_ns)\n",
            "  File \"<ipython-input-127-cdd8f5eda548>\", line 3, in <cell line: 3>\n",
            "    f = open('/content/IKDSumm_Uflood.txt\"', \"r\", encoding=\"utf8\")\n",
            "FileNotFoundError: [Errno 2] No such file or directory: '/content/IKDSumm_Uflood.txt\"'\n",
            "\n",
            "During handling of the above exception, another exception occurred:\n",
            "\n",
            "Traceback (most recent call last):\n",
            "  File \"/usr/local/lib/python3.10/dist-packages/IPython/core/interactiveshell.py\", line 2099, in showtraceback\n",
            "    stb = value._render_traceback_()\n",
            "AttributeError: 'FileNotFoundError' object has no attribute '_render_traceback_'\n",
            "\n",
            "During handling of the above exception, another exception occurred:\n",
            "\n",
            "Traceback (most recent call last):\n",
            "  File \"/usr/local/lib/python3.10/dist-packages/IPython/core/interactiveshell.py\", line 3473, in run_ast_nodes\n",
            "    if (await self.run_code(code, result,  async_=asy)):\n",
            "  File \"/usr/local/lib/python3.10/dist-packages/IPython/core/interactiveshell.py\", line 3575, in run_code\n",
            "    self.showtraceback(running_compiled_code=True)\n",
            "  File \"/usr/local/lib/python3.10/dist-packages/IPython/core/interactiveshell.py\", line 2101, in showtraceback\n",
            "    stb = self.InteractiveTB.structured_traceback(etype,\n",
            "  File \"/usr/local/lib/python3.10/dist-packages/IPython/core/ultratb.py\", line 1367, in structured_traceback\n",
            "    return FormattedTB.structured_traceback(\n",
            "  File \"/usr/local/lib/python3.10/dist-packages/IPython/core/ultratb.py\", line 1267, in structured_traceback\n",
            "    return VerboseTB.structured_traceback(\n",
            "  File \"/usr/local/lib/python3.10/dist-packages/IPython/core/ultratb.py\", line 1124, in structured_traceback\n",
            "    formatted_exception = self.format_exception_as_a_whole(etype, evalue, etb, number_of_lines_of_context,\n",
            "  File \"/usr/local/lib/python3.10/dist-packages/IPython/core/ultratb.py\", line 1082, in format_exception_as_a_whole\n",
            "    last_unique, recursion_repeat = find_recursion(orig_etype, evalue, records)\n",
            "  File \"/usr/local/lib/python3.10/dist-packages/IPython/core/ultratb.py\", line 382, in find_recursion\n",
            "    return len(records), 0\n",
            "TypeError: object of type 'NoneType' has no len()\n",
            "\n",
            "During handling of the above exception, another exception occurred:\n",
            "\n",
            "Traceback (most recent call last):\n",
            "  File \"/usr/local/lib/python3.10/dist-packages/IPython/core/interactiveshell.py\", line 2099, in showtraceback\n",
            "    stb = value._render_traceback_()\n",
            "AttributeError: 'TypeError' object has no attribute '_render_traceback_'\n",
            "\n",
            "During handling of the above exception, another exception occurred:\n",
            "\n",
            "Traceback (most recent call last):\n",
            "  File \"/usr/local/lib/python3.10/dist-packages/IPython/core/interactiveshell.py\", line 3030, in _run_cell\n",
            "    return runner(coro)\n",
            "  File \"/usr/local/lib/python3.10/dist-packages/IPython/core/async_helpers.py\", line 78, in _pseudo_sync_runner\n",
            "    coro.send(None)\n",
            "  File \"/usr/local/lib/python3.10/dist-packages/IPython/core/interactiveshell.py\", line 3257, in run_cell_async\n",
            "    has_raised = await self.run_ast_nodes(code_ast.body, cell_name,\n",
            "  File \"/usr/local/lib/python3.10/dist-packages/IPython/core/interactiveshell.py\", line 3492, in run_ast_nodes\n",
            "    self.showtraceback()\n",
            "  File \"/usr/local/lib/python3.10/dist-packages/IPython/core/interactiveshell.py\", line 2101, in showtraceback\n",
            "    stb = self.InteractiveTB.structured_traceback(etype,\n",
            "  File \"/usr/local/lib/python3.10/dist-packages/IPython/core/ultratb.py\", line 1367, in structured_traceback\n",
            "    return FormattedTB.structured_traceback(\n",
            "  File \"/usr/local/lib/python3.10/dist-packages/IPython/core/ultratb.py\", line 1267, in structured_traceback\n",
            "    return VerboseTB.structured_traceback(\n",
            "  File \"/usr/local/lib/python3.10/dist-packages/IPython/core/ultratb.py\", line 1142, in structured_traceback\n",
            "    formatted_exceptions += self.format_exception_as_a_whole(etype, evalue, etb, lines_of_context,\n",
            "  File \"/usr/local/lib/python3.10/dist-packages/IPython/core/ultratb.py\", line 1082, in format_exception_as_a_whole\n",
            "    last_unique, recursion_repeat = find_recursion(orig_etype, evalue, records)\n",
            "  File \"/usr/local/lib/python3.10/dist-packages/IPython/core/ultratb.py\", line 382, in find_recursion\n",
            "    return len(records), 0\n",
            "TypeError: object of type 'NoneType' has no len()\n",
            "\n",
            "During handling of the above exception, another exception occurred:\n",
            "\n",
            "Traceback (most recent call last):\n",
            "  File \"/usr/local/lib/python3.10/dist-packages/IPython/core/interactiveshell.py\", line 2099, in showtraceback\n",
            "    stb = value._render_traceback_()\n",
            "AttributeError: 'TypeError' object has no attribute '_render_traceback_'\n",
            "\n",
            "During handling of the above exception, another exception occurred:\n",
            "\n",
            "Traceback (most recent call last):\n",
            "  File \"/usr/local/lib/python3.10/dist-packages/IPython/core/ultratb.py\", line 1101, in get_records\n",
            "    return _fixed_getinnerframes(etb, number_of_lines_of_context, tb_offset)\n",
            "  File \"/usr/local/lib/python3.10/dist-packages/IPython/core/ultratb.py\", line 248, in wrapped\n",
            "    return f(*args, **kwargs)\n",
            "  File \"/usr/local/lib/python3.10/dist-packages/IPython/core/ultratb.py\", line 281, in _fixed_getinnerframes\n",
            "    records = fix_frame_records_filenames(inspect.getinnerframes(etb, context))\n",
            "  File \"/usr/lib/python3.10/inspect.py\", line 1662, in getinnerframes\n",
            "    frameinfo = (tb.tb_frame,) + getframeinfo(tb, context)\n",
            "  File \"/usr/lib/python3.10/inspect.py\", line 1620, in getframeinfo\n",
            "    filename = getsourcefile(frame) or getfile(frame)\n",
            "  File \"/usr/lib/python3.10/inspect.py\", line 829, in getsourcefile\n",
            "    module = getmodule(object, filename)\n",
            "  File \"/usr/lib/python3.10/inspect.py\", line 861, in getmodule\n",
            "    file = getabsfile(object, _filename)\n",
            "  File \"/usr/lib/python3.10/inspect.py\", line 845, in getabsfile\n",
            "    return os.path.normcase(os.path.abspath(_filename))\n",
            "  File \"/usr/lib/python3.10/posixpath.py\", line 384, in abspath\n",
            "    cwd = os.getcwd()\n",
            "OSError: [Errno 107] Transport endpoint is not connected\n"
          ]
        }
      ],
      "source": [
        "input_tweets=[]\n",
        "t=' '\n",
        "f = open('/content/IKDSumm_Uflood.txt\"', \"r\", encoding=\"utf8\")\n",
        "for x in f:\n",
        "  t=t+x+' '\n",
        "  input_tweets.append(t)\n",
        "\n",
        "genertaed_summary=[]\n",
        "inputs = tokenizer(\"summarize: \" + t, return_tensors=\"pt\", max_length=512, truncation=True)\n",
        "outputs = sum_model.generate(inputs[\"input_ids\"], max_length=200, min_length=150, length_penalty=4.0, num_beams=4, early_stopping=True)\n",
        "gs = tokenizer.decode(outputs[0])[6:-4]\n",
        "genertaed_summary.append(gs)"
      ]
    },
    {
      "cell_type": "code",
      "execution_count": null,
      "metadata": {
        "colab": {
          "background_save": true,
          "base_uri": "https://localhost:8080/"
        },
        "id": "DatqLx85A2ZP",
        "outputId": "5e0a1661-2e2c-4bcb-9ff2-44b541066ce8"
      },
      "outputs": [
        {
          "name": "stderr",
          "output_type": "stream",
          "text": [
            "ERROR:root:Internal Python error in the inspect module.\n",
            "Below is the traceback from this internal error.\n",
            "\n",
            "ERROR:root:Internal Python error in the inspect module.\n",
            "Below is the traceback from this internal error.\n",
            "\n",
            "ERROR:root:Internal Python error in the inspect module.\n",
            "Below is the traceback from this internal error.\n",
            "\n"
          ]
        },
        {
          "name": "stdout",
          "output_type": "stream",
          "text": [
            "Traceback (most recent call last):\n",
            "  File \"/usr/local/lib/python3.10/dist-packages/IPython/core/interactiveshell.py\", line 3553, in run_code\n",
            "    exec(code_obj, self.user_global_ns, self.user_ns)\n",
            "  File \"<ipython-input-127-b7ae56f0e7c6>\", line 1, in <cell line: 1>\n",
            "    generated_summary\n",
            "NameError: name 'generated_summary' is not defined\n",
            "\n",
            "During handling of the above exception, another exception occurred:\n",
            "\n",
            "Traceback (most recent call last):\n",
            "  File \"/usr/local/lib/python3.10/dist-packages/IPython/core/interactiveshell.py\", line 2099, in showtraceback\n",
            "    stb = value._render_traceback_()\n",
            "AttributeError: 'NameError' object has no attribute '_render_traceback_'\n",
            "\n",
            "During handling of the above exception, another exception occurred:\n",
            "\n",
            "Traceback (most recent call last):\n",
            "  File \"/usr/local/lib/python3.10/dist-packages/IPython/core/ultratb.py\", line 1101, in get_records\n",
            "    return _fixed_getinnerframes(etb, number_of_lines_of_context, tb_offset)\n",
            "  File \"/usr/local/lib/python3.10/dist-packages/IPython/core/ultratb.py\", line 248, in wrapped\n",
            "    return f(*args, **kwargs)\n",
            "  File \"/usr/local/lib/python3.10/dist-packages/IPython/core/ultratb.py\", line 281, in _fixed_getinnerframes\n",
            "    records = fix_frame_records_filenames(inspect.getinnerframes(etb, context))\n",
            "  File \"/usr/lib/python3.10/inspect.py\", line 1662, in getinnerframes\n",
            "    frameinfo = (tb.tb_frame,) + getframeinfo(tb, context)\n",
            "  File \"/usr/lib/python3.10/inspect.py\", line 1620, in getframeinfo\n",
            "    filename = getsourcefile(frame) or getfile(frame)\n",
            "  File \"/usr/lib/python3.10/inspect.py\", line 829, in getsourcefile\n",
            "    module = getmodule(object, filename)\n",
            "  File \"/usr/lib/python3.10/inspect.py\", line 861, in getmodule\n",
            "    file = getabsfile(object, _filename)\n",
            "  File \"/usr/lib/python3.10/inspect.py\", line 845, in getabsfile\n",
            "    return os.path.normcase(os.path.abspath(_filename))\n",
            "  File \"/usr/lib/python3.10/posixpath.py\", line 384, in abspath\n",
            "    cwd = os.getcwd()\n",
            "OSError: [Errno 107] Transport endpoint is not connected\n",
            "Traceback (most recent call last):\n",
            "  File \"/usr/local/lib/python3.10/dist-packages/IPython/core/interactiveshell.py\", line 3553, in run_code\n",
            "    exec(code_obj, self.user_global_ns, self.user_ns)\n",
            "  File \"<ipython-input-127-b7ae56f0e7c6>\", line 1, in <cell line: 1>\n",
            "    generated_summary\n",
            "NameError: name 'generated_summary' is not defined\n",
            "\n",
            "During handling of the above exception, another exception occurred:\n",
            "\n",
            "Traceback (most recent call last):\n",
            "  File \"/usr/local/lib/python3.10/dist-packages/IPython/core/interactiveshell.py\", line 2099, in showtraceback\n",
            "    stb = value._render_traceback_()\n",
            "AttributeError: 'NameError' object has no attribute '_render_traceback_'\n",
            "\n",
            "During handling of the above exception, another exception occurred:\n",
            "\n",
            "Traceback (most recent call last):\n",
            "  File \"/usr/local/lib/python3.10/dist-packages/IPython/core/interactiveshell.py\", line 3473, in run_ast_nodes\n",
            "    if (await self.run_code(code, result,  async_=asy)):\n",
            "  File \"/usr/local/lib/python3.10/dist-packages/IPython/core/interactiveshell.py\", line 3575, in run_code\n",
            "    self.showtraceback(running_compiled_code=True)\n",
            "  File \"/usr/local/lib/python3.10/dist-packages/IPython/core/interactiveshell.py\", line 2101, in showtraceback\n",
            "    stb = self.InteractiveTB.structured_traceback(etype,\n",
            "  File \"/usr/local/lib/python3.10/dist-packages/IPython/core/ultratb.py\", line 1367, in structured_traceback\n",
            "    return FormattedTB.structured_traceback(\n",
            "  File \"/usr/local/lib/python3.10/dist-packages/IPython/core/ultratb.py\", line 1267, in structured_traceback\n",
            "    return VerboseTB.structured_traceback(\n",
            "  File \"/usr/local/lib/python3.10/dist-packages/IPython/core/ultratb.py\", line 1124, in structured_traceback\n",
            "    formatted_exception = self.format_exception_as_a_whole(etype, evalue, etb, number_of_lines_of_context,\n",
            "  File \"/usr/local/lib/python3.10/dist-packages/IPython/core/ultratb.py\", line 1082, in format_exception_as_a_whole\n",
            "    last_unique, recursion_repeat = find_recursion(orig_etype, evalue, records)\n",
            "  File \"/usr/local/lib/python3.10/dist-packages/IPython/core/ultratb.py\", line 382, in find_recursion\n",
            "    return len(records), 0\n",
            "TypeError: object of type 'NoneType' has no len()\n",
            "\n",
            "During handling of the above exception, another exception occurred:\n",
            "\n",
            "Traceback (most recent call last):\n",
            "  File \"/usr/local/lib/python3.10/dist-packages/IPython/core/interactiveshell.py\", line 2099, in showtraceback\n",
            "    stb = value._render_traceback_()\n",
            "AttributeError: 'TypeError' object has no attribute '_render_traceback_'\n",
            "\n",
            "During handling of the above exception, another exception occurred:\n",
            "\n",
            "Traceback (most recent call last):\n",
            "  File \"/usr/local/lib/python3.10/dist-packages/IPython/core/ultratb.py\", line 1101, in get_records\n",
            "    return _fixed_getinnerframes(etb, number_of_lines_of_context, tb_offset)\n",
            "  File \"/usr/local/lib/python3.10/dist-packages/IPython/core/ultratb.py\", line 248, in wrapped\n",
            "    return f(*args, **kwargs)\n",
            "  File \"/usr/local/lib/python3.10/dist-packages/IPython/core/ultratb.py\", line 281, in _fixed_getinnerframes\n",
            "    records = fix_frame_records_filenames(inspect.getinnerframes(etb, context))\n",
            "  File \"/usr/lib/python3.10/inspect.py\", line 1662, in getinnerframes\n",
            "    frameinfo = (tb.tb_frame,) + getframeinfo(tb, context)\n",
            "  File \"/usr/lib/python3.10/inspect.py\", line 1620, in getframeinfo\n",
            "    filename = getsourcefile(frame) or getfile(frame)\n",
            "  File \"/usr/lib/python3.10/inspect.py\", line 829, in getsourcefile\n",
            "    module = getmodule(object, filename)\n",
            "  File \"/usr/lib/python3.10/inspect.py\", line 861, in getmodule\n",
            "    file = getabsfile(object, _filename)\n",
            "  File \"/usr/lib/python3.10/inspect.py\", line 845, in getabsfile\n",
            "    return os.path.normcase(os.path.abspath(_filename))\n",
            "  File \"/usr/lib/python3.10/posixpath.py\", line 384, in abspath\n",
            "    cwd = os.getcwd()\n",
            "OSError: [Errno 107] Transport endpoint is not connected\n",
            "Traceback (most recent call last):\n",
            "  File \"/usr/local/lib/python3.10/dist-packages/IPython/core/interactiveshell.py\", line 3553, in run_code\n",
            "    exec(code_obj, self.user_global_ns, self.user_ns)\n",
            "  File \"<ipython-input-127-b7ae56f0e7c6>\", line 1, in <cell line: 1>\n",
            "    generated_summary\n",
            "NameError: name 'generated_summary' is not defined\n",
            "\n",
            "During handling of the above exception, another exception occurred:\n",
            "\n",
            "Traceback (most recent call last):\n",
            "  File \"/usr/local/lib/python3.10/dist-packages/IPython/core/interactiveshell.py\", line 2099, in showtraceback\n",
            "    stb = value._render_traceback_()\n",
            "AttributeError: 'NameError' object has no attribute '_render_traceback_'\n",
            "\n",
            "During handling of the above exception, another exception occurred:\n",
            "\n",
            "Traceback (most recent call last):\n",
            "  File \"/usr/local/lib/python3.10/dist-packages/IPython/core/interactiveshell.py\", line 3473, in run_ast_nodes\n",
            "    if (await self.run_code(code, result,  async_=asy)):\n",
            "  File \"/usr/local/lib/python3.10/dist-packages/IPython/core/interactiveshell.py\", line 3575, in run_code\n",
            "    self.showtraceback(running_compiled_code=True)\n",
            "  File \"/usr/local/lib/python3.10/dist-packages/IPython/core/interactiveshell.py\", line 2101, in showtraceback\n",
            "    stb = self.InteractiveTB.structured_traceback(etype,\n",
            "  File \"/usr/local/lib/python3.10/dist-packages/IPython/core/ultratb.py\", line 1367, in structured_traceback\n",
            "    return FormattedTB.structured_traceback(\n",
            "  File \"/usr/local/lib/python3.10/dist-packages/IPython/core/ultratb.py\", line 1267, in structured_traceback\n",
            "    return VerboseTB.structured_traceback(\n",
            "  File \"/usr/local/lib/python3.10/dist-packages/IPython/core/ultratb.py\", line 1124, in structured_traceback\n",
            "    formatted_exception = self.format_exception_as_a_whole(etype, evalue, etb, number_of_lines_of_context,\n",
            "  File \"/usr/local/lib/python3.10/dist-packages/IPython/core/ultratb.py\", line 1082, in format_exception_as_a_whole\n",
            "    last_unique, recursion_repeat = find_recursion(orig_etype, evalue, records)\n",
            "  File \"/usr/local/lib/python3.10/dist-packages/IPython/core/ultratb.py\", line 382, in find_recursion\n",
            "    return len(records), 0\n",
            "TypeError: object of type 'NoneType' has no len()\n",
            "\n",
            "During handling of the above exception, another exception occurred:\n",
            "\n",
            "Traceback (most recent call last):\n",
            "  File \"/usr/local/lib/python3.10/dist-packages/IPython/core/interactiveshell.py\", line 2099, in showtraceback\n",
            "    stb = value._render_traceback_()\n",
            "AttributeError: 'TypeError' object has no attribute '_render_traceback_'\n",
            "\n",
            "During handling of the above exception, another exception occurred:\n",
            "\n",
            "Traceback (most recent call last):\n",
            "  File \"/usr/local/lib/python3.10/dist-packages/IPython/core/interactiveshell.py\", line 3030, in _run_cell\n",
            "    return runner(coro)\n",
            "  File \"/usr/local/lib/python3.10/dist-packages/IPython/core/async_helpers.py\", line 78, in _pseudo_sync_runner\n",
            "    coro.send(None)\n",
            "  File \"/usr/local/lib/python3.10/dist-packages/IPython/core/interactiveshell.py\", line 3257, in run_cell_async\n",
            "    has_raised = await self.run_ast_nodes(code_ast.body, cell_name,\n",
            "  File \"/usr/local/lib/python3.10/dist-packages/IPython/core/interactiveshell.py\", line 3492, in run_ast_nodes\n",
            "    self.showtraceback()\n",
            "  File \"/usr/local/lib/python3.10/dist-packages/IPython/core/interactiveshell.py\", line 2101, in showtraceback\n",
            "    stb = self.InteractiveTB.structured_traceback(etype,\n",
            "  File \"/usr/local/lib/python3.10/dist-packages/IPython/core/ultratb.py\", line 1367, in structured_traceback\n",
            "    return FormattedTB.structured_traceback(\n",
            "  File \"/usr/local/lib/python3.10/dist-packages/IPython/core/ultratb.py\", line 1267, in structured_traceback\n",
            "    return VerboseTB.structured_traceback(\n",
            "  File \"/usr/local/lib/python3.10/dist-packages/IPython/core/ultratb.py\", line 1142, in structured_traceback\n",
            "    formatted_exceptions += self.format_exception_as_a_whole(etype, evalue, etb, lines_of_context,\n",
            "  File \"/usr/local/lib/python3.10/dist-packages/IPython/core/ultratb.py\", line 1082, in format_exception_as_a_whole\n",
            "    last_unique, recursion_repeat = find_recursion(orig_etype, evalue, records)\n",
            "  File \"/usr/local/lib/python3.10/dist-packages/IPython/core/ultratb.py\", line 382, in find_recursion\n",
            "    return len(records), 0\n",
            "TypeError: object of type 'NoneType' has no len()\n",
            "\n",
            "During handling of the above exception, another exception occurred:\n",
            "\n",
            "Traceback (most recent call last):\n",
            "  File \"/usr/local/lib/python3.10/dist-packages/IPython/core/interactiveshell.py\", line 2099, in showtraceback\n",
            "    stb = value._render_traceback_()\n",
            "AttributeError: 'TypeError' object has no attribute '_render_traceback_'\n",
            "\n",
            "During handling of the above exception, another exception occurred:\n",
            "\n",
            "Traceback (most recent call last):\n",
            "  File \"/usr/local/lib/python3.10/dist-packages/IPython/core/ultratb.py\", line 1101, in get_records\n",
            "    return _fixed_getinnerframes(etb, number_of_lines_of_context, tb_offset)\n",
            "  File \"/usr/local/lib/python3.10/dist-packages/IPython/core/ultratb.py\", line 248, in wrapped\n",
            "    return f(*args, **kwargs)\n",
            "  File \"/usr/local/lib/python3.10/dist-packages/IPython/core/ultratb.py\", line 281, in _fixed_getinnerframes\n",
            "    records = fix_frame_records_filenames(inspect.getinnerframes(etb, context))\n",
            "  File \"/usr/lib/python3.10/inspect.py\", line 1662, in getinnerframes\n",
            "    frameinfo = (tb.tb_frame,) + getframeinfo(tb, context)\n",
            "  File \"/usr/lib/python3.10/inspect.py\", line 1620, in getframeinfo\n",
            "    filename = getsourcefile(frame) or getfile(frame)\n",
            "  File \"/usr/lib/python3.10/inspect.py\", line 829, in getsourcefile\n",
            "    module = getmodule(object, filename)\n",
            "  File \"/usr/lib/python3.10/inspect.py\", line 861, in getmodule\n",
            "    file = getabsfile(object, _filename)\n",
            "  File \"/usr/lib/python3.10/inspect.py\", line 845, in getabsfile\n",
            "    return os.path.normcase(os.path.abspath(_filename))\n",
            "  File \"/usr/lib/python3.10/posixpath.py\", line 384, in abspath\n",
            "    cwd = os.getcwd()\n",
            "OSError: [Errno 107] Transport endpoint is not connected\n"
          ]
        }
      ],
      "source": [
        "generated_summary"
      ]
    }
  ],
  "metadata": {
    "colab": {
      "provenance": [],
      "include_colab_link": true
    },
    "kernelspec": {
      "display_name": "Python 3",
      "name": "python3"
    },
    "language_info": {
      "name": "python"
    }
  },
  "nbformat": 4,
  "nbformat_minor": 0
}